Workbook
Name Slicer_Department: #N/A
Name Slicer_Employment_Status: #N/A
Name Slicer_Gender: #N/A
Name Slicer_Hire_Date__Year: #N/A
Name Slicer_Region: #N/A

Sheet DATA HR EMPLOYEE
A1: Employee ID | B1: Employee Name | C1: Gender | D1: Age | E1: Department | F1: Job Role | G1: Hire Date | H1: Employment Status | I1: Resignation Date | J1: Education Level | K1: Region | L1: Monthly Salary | M1: Salary Category | N1: Bonus | O1: Performance Score | P1: Overtime Hours | Q1: Attendance Rate (%) | R1: Years at Company | S1: Job Satisfaction
A2: EMP000001 | B2: Employee_1 | C2: Female | D2: 48 | E2: Sales | F2: Sales Manager | G2: 43615 | H2: Active | J2: Master | K2: Bandung | L2: 18831984 | M2: =IF(L2<5000000,"<Rp5 jt",IF(L2<10000000,"Rp5 jt - Rp10 jt",IF(L2<15000000,"Rp10 jt - Rp15 jt",IF(L2<25000000,"Rp15 jt - Rp25 jt",">Rp25 jt")))) -> Rp15 jt - Rp25 jt | N2: 5723038 | O2: 4.91 | P2: 15 | Q2: 98.03 | R2: =IF(I2="",ROUND((TODAY()-G2)/365,1),ROUND((hr_analytics_dataset_5873_rows[[#This Row],[Resignation Date]]-hr_analytics_dataset_5873_rows[[#This Row],[Hire Date]])/365,1)) -> 7.1 | S2: 4
A3: EMP000002 | B3: Employee_2 | C3: Male | D3: 26 | E3: IT | F3: System Admin | G3: 44130 | H3: Resigned | I3: 46116 | J3: Diploma | K3: Bandung | L3: 33418624 | M3: =IF(L3<5000000,"<Rp5 jt",IF(L3<10000000,"Rp5 jt - Rp10 jt",IF(L3<15000000,"Rp10 jt - Rp15 jt",IF(L3<25000000,"Rp15 jt - Rp25 jt",">Rp25 jt")))) -> >Rp25 jt | N3: 541210 | O3: 3.47 | P3: 55 | Q3: 99.01 | R3: =IF(I3="",ROUND((TODAY()-G3)/365,1),ROUND((hr_analytics_dataset_5873_rows[[#This Row],[Resignation Date]]-hr_analytics_dataset_5873_rows[[#This Row],[Hire Date]])/365,1)) -> 5.4 | S3: 4 | V3: Jumlah Karyawan | W3: =COUNTA(hr_analytics_dataset_5873_rows[Employee ID]) -> 5873
A4: EMP000003 | B4: Employee_3 | C4: Female | D4: 36 | E4: Operations | F4: Operations Manager | G4: 45785 | H4: Active | J4: High School | K4: Surabaya | L4: 15519850 | M4: =IF(L4<5000000,"<Rp5 jt",IF(L4<10000000,"Rp5 jt - Rp10 jt",IF(L4<15000000,"Rp10 jt - Rp15 jt",IF(L4<25000000,"Rp15 jt - Rp25 jt",">Rp25 jt")))) -> Rp15 jt - Rp25 jt | N4: 1322362 | O4: 3.13 | P4: 46 | Q4: 80.86 | R4: =IF(I4="",ROUND((TODAY()-G4)/365,1),ROUND((hr_analytics_dataset_5873_rows[[#This Row],[Resignation Date]]-hr_analytics_dataset_5873_rows[[#This Row],[Hire Date]])/365,1)) -> 1.1 | S4: 2 | W4: =COUNTA(_xlfn.UNIQUE(hr_analytics_dataset_5873_rows[Employee ID])) -> 5873
A5: EMP000004 | B5: Employee_4 | C5: Female | D5: 39 | E5: Marketing | F5: Marketing Executive | G5: 44246 | H5: Active | J5: High School | K5: Bandung | L5: 7673135 | M5: =IF(L5<5000000,"<Rp5 jt",IF(L5<10000000,"Rp5 jt - Rp10 jt",IF(L5<15000000,"Rp10 jt - Rp15 jt",IF(L5<25000000,"Rp15 jt - Rp25 jt",">Rp25 jt")))) -> Rp5 jt - Rp10 jt | N5: 5803373 | O5: 4.48 | P5: 58 | Q5: 97.08 | R5: =IF(I5="",ROUND((TODAY()-G5)/365,1),ROUND((hr_analytics_dataset_5873_rows[[#This Row],[Resignation Date]]-hr_analytics_dataset_5873_rows[[#This Row],[Hire Date]])/365,1)) -> 5.3 | S5: 3
A6: EMP000005 | B6: Employee_5 | C6: Male | D6: 56 | E6: IT | F6: Data Analyst | G6: 45108 | H6: Resigned | I6: 46072 | J6: Bachelor | K6: Semarang | L6: 25941260 | M6: =IF(L6<5000000,"<Rp5 jt",IF(L6<10000000,"Rp5 jt - Rp10 jt",IF(L6<15000000,"Rp10 jt - Rp15 jt",IF(L6<25000000,"Rp15 jt - Rp25 jt",">Rp25 jt")))) -> >Rp25 jt | N6: 1286723 | O6: 3.43 | P6: 19 | Q6: 75.48 | R6: =IF(I6="",ROUND((TODAY()-G6)/365,1),ROUND((hr_analytics_dataset_5873_rows[[#This Row],[Resignation Date]]-hr_analytics_dataset_5873_rows[[#This Row],[Hire Date]])/365,1)) -> 2.6 | S6: 1
A7: EMP000006 | B7: Employee_6 | C7: Male | D7: 57 | E7: Logistics | F7: Supply Chain Analyst | G7: 45070 | H7: Active | J7: Diploma | K7: Surabaya | L7: 26677346 | M7: =IF(L7<5000000,"<Rp5 jt",IF(L7<10000000,"Rp5 jt - Rp10 jt",IF(L7<15000000,"Rp10 jt - Rp15 jt",IF(L7<25000000,"Rp15 jt - Rp25 jt",">Rp25 jt")))) -> >Rp25 jt | N7: 9908304 | O7: 3.36 | P7: 15 | Q7: 78.65 | R7: =IF(I7="",ROUND((TODAY()-G7)/365,1),ROUND((hr_analytics_dataset_5873_rows[[#This Row],[Resignation Date]]-hr_analytics_dataset_5873_rows[[#This Row],[Hire Date]])/365,1)) -> 3.1 | S7: 4
A8: EMP000007 | B8: Employee_7 | C8: Female | D8: 24 | E8: Logistics | F8: Supply Chain Analyst | G8: 43562 | H8: Active | J8: Bachelor | K8: Bandung | L8: 25806571 | M8: =IF(L8<5000000,"<Rp5 jt",IF(L8<10000000,"Rp5 jt - Rp10 jt",IF(L8<15000000,"Rp10 jt - Rp15 jt",IF(L8<25000000,"Rp15 jt - Rp25 jt",">Rp25 jt")))) -> >Rp25 jt | N8: 3832514 | O8: 3.93 | P8: 34 | Q8: 87.43 | R8: =IF(I8="",ROUND((TODAY()-G8)/365,1),ROUND((hr_analytics_dataset_5873_rows[[#This Row],[Resignation Date]]-hr_analytics_dataset_5873_rows[[#This Row],[Hire Date]])/365,1)) -> 7.2 | S8: 5
A9: EMP000008 | B9: Employee_8 | C9: Female | D9: 28 | E9: HR | F9: Recruiter | G9: 45823 | H9: Active | J9: Bachelor | K9: Medan | L9: 14576147 | M9: =IF(L9<5000000,"<Rp5 jt",IF(L9<10000000,"Rp5 jt - Rp10 jt",IF(L9<15000000,"Rp10 jt - Rp15 jt",IF(L9<25000000,"Rp15 jt - Rp25 jt",">Rp25 jt")))) -> Rp10 jt - Rp15 jt | N9: 5328081 | O9: 4.65 | P9: 20 | Q9: 70.49 | R9: =IF(I9="",ROUND((TODAY()-G9)/365,1),ROUND((hr_analytics_dataset_5873_rows[[#This Row],[Resignation Date]]-hr_analytics_dataset_5873_rows[[#This Row],[Hire Date]])/365,1)) -> 1 | S9: 2
A10: EMP000009 | B10: Employee_9 | C10: Female | D10: 44 | E10: Operations | F10: Operations Manager | G10: 44292 | H10: Active | J10: Master | K10: Yogyakarta | L10: 28171681 | M10: =IF(L10<5000000,"<Rp5 jt",IF(L10<10000000,"Rp5 jt - Rp10 jt",IF(L10<15000000,"Rp10 jt - Rp15 jt",IF(L10<25000000,"Rp15 jt - Rp25 jt",">Rp25 jt")))) -> >Rp25 jt | N10: 2716525 | O10: 4.78 | P10: 43 | Q10: 76.19 | R10: =IF(I10="",ROUND((TODAY()-G10)/365,1),ROUND((hr_analytics_dataset_5873_rows[[#This Row],[Resignation Date]]-hr_analytics_dataset_5873_rows[[#This Row],[Hire Date]])/365,1)) -> 5.2 | S10: 1
A11: EMP000010 | B11: Employee_10 | C11: Male | D11: 27 | E11: Operations | F11: Operations Manager | G11: 44168 | H11: Resigned | I11: 45722 | J11: High School | K11: Bandung | L11: 11630453 | M11: =IF(L11<5000000,"<Rp5 jt",IF(L11<10000000,"Rp5 jt - Rp10 jt",IF(L11<15000000,"Rp10 jt - Rp15 jt",IF(L11<25000000,"Rp15 jt - Rp25 jt",">Rp25 jt")))) -> Rp10 jt - Rp15 jt | N11: 2850529 | O11: 4.52 | P11: 18 | Q11: 97.16 | R11: =IF(I11="",ROUND((TODAY()-G11)/365,1),ROUND((hr_analytics_dataset_5873_rows[[#This Row],[Resignation Date]]-hr_analytics_dataset_5873_rows[[#This Row],[Hire Date]])/365,1)) -> 4.3 | S11: 3
A12: EMP000011 | B12: Employee_11 | C12: Female | D12: 44 | E12: Sales | F12: Sales Executive | G12: 45656 | H12: Active | J12: Bachelor | K12: Medan | L12: 24453900 | M12: =IF(L12<5000000,"<Rp5 jt",IF(L12<10000000,"Rp5 jt - Rp10 jt",IF(L12<15000000,"Rp10 jt - Rp15 jt",IF(L12<25000000,"Rp15 jt - Rp25 jt",">Rp25 jt")))) -> Rp15 jt - Rp25 jt | N12: 3194035 | O12: 2.98 | P12: 18 | Q12: 88.68 | R12: =IF(I12="",ROUND((TODAY()-G12)/365,1),ROUND((hr_analytics_dataset_5873_rows[[#This Row],[Resignation Date]]-hr_analytics_dataset_5873_rows[[#This Row],[Hire Date]])/365,1)) -> 1.5 | S12: 2
A13: EMP000012 | B13: Employee_12 | C13: Male | D13: 33 | E13: Sales | F13: Sales Executive | G13: 44772 | H13: Active | J13: Bachelor | K13: Yogyakarta | L13: 29873807 | M13: =IF(L13<5000000,"<Rp5 jt",IF(L13<10000000,"Rp5 jt - Rp10 jt",IF(L13<15000000,"Rp10 jt - Rp15 jt",IF(L13<25000000,"Rp15 jt - Rp25 jt",">Rp25 jt")))) -> >Rp25 jt | N13: 8723283 | O13: 3.18 | P13: 20 | Q13: 85.92 | R13: =IF(I13="",ROUND((TODAY()-G13)/365,1),ROUND((hr_analytics_dataset_5873_rows[[#This Row],[Resignation Date]]-hr_analytics_dataset_5873_rows[[#This Row],[Hire Date]])/365,1)) -> 3.9 | S13: 5
A14: EMP000013 | B14: Employee_13 | C14: Male | D14: 23 | E14: IT | F14: Software Engineer | G14: 45020 | H14: Resigned | I14: 45570 | J14: Bachelor | K14: Surabaya | L14: 15446940 | M14: =IF(L14<5000000,"<Rp5 jt",IF(L14<10000000,"Rp5 jt - Rp10 jt",IF(L14<15000000,"Rp10 jt - Rp15 jt",IF(L14<25000000,"Rp15 jt - Rp25 jt",">Rp25 jt")))) -> Rp15 jt - Rp25 jt | N14: 8647617 | O14: 3.38 | P14: 55 | Q14: 77.21 | R14: =IF(I14="",ROUND((TODAY()-G14)/365,1),ROUND((hr_analytics_dataset_5873_rows[[#This Row],[Resignation Date]]-hr_analytics_dataset_5873_rows[[#This Row],[Hire Date]])/365,1)) -> 1.5 | S14: 1
A15: EMP000014 | B15: Employee_14 | C15: Female | D15: 21 | E15: Marketing | F15: Marketing Executive | G15: 45685 | H15: Active | J15: Diploma | K15: Bandung | L15: 20694172 | M15: =IF(L15<5000000,"<Rp5 jt",IF(L15<10000000,"Rp5 jt - Rp10 jt",IF(L15<15000000,"Rp10 jt - Rp15 jt",IF(L15<25000000,"Rp15 jt - Rp25 jt",">Rp25 jt")))) -> Rp15 jt - Rp25 jt | N15: 2767849 | O15: 4.44 | P15: 21 | Q15: 75.69 | R15: =IF(I15="",ROUND((TODAY()-G15)/365,1),ROUND((hr_analytics_dataset_5873_rows[[#This Row],[Resignation Date]]-hr_analytics_dataset_5873_rows[[#This Row],[Hire Date]])/365,1)) -> 1.4 | S15: 1
A16: EMP000015 | B16: Employee_15 | C16: Male | D16: 38 | E16: Logistics | F16: Supply Chain Analyst | G16: 43455 | H16: Resigned | I16: 44277 | J16: Master | K16: Surabaya | L16: 33973726 | M16: =IF(L16<5000000,"<Rp5 jt",IF(L16<10000000,"Rp5 jt - Rp10 jt",IF(L16<15000000,"Rp10 jt - Rp15 jt",IF(L16<25000000,"Rp15 jt - Rp25 jt",">Rp25 jt")))) -> >Rp25 jt | N16: 7078185 | O16: 2.72 | P16: 26 | Q16: 86.34 | R16: =IF(I16="",ROUND((TODAY()-G16)/365,1),ROUND((hr_analytics_dataset_5873_rows[[#This Row],[Resignation Date]]-hr_analytics_dataset_5873_rows[[#This Row],[Hire Date]])/365,1)) -> 2.3 | S16: 2
A17: EMP000016 | B17: Employee_16 | C17: Male | D17: 35 | E17: Marketing | F17: Marketing Executive | G17: 45306 | H17: Resigned | I17: Missing Resignation Date | J17: Diploma | K17: Bandung | L17: 15971299 | M17: =IF(L17<5000000,"<Rp5 jt",IF(L17<10000000,"Rp5 jt - Rp10 jt",IF(L17<15000000,"Rp10 jt - Rp15 jt",IF(L17<25000000,"Rp15 jt - Rp25 jt",">Rp25 jt")))) -> Rp15 jt - Rp25 jt | N17: 320559 | O17: 4.74 | P17: 18 | Q17: 79.8 | R17: =IF(I17="",ROUND((TODAY()-G17)/365,1),IF(I17="Missing Resignation Date",ROUND((TODAY()-G17)/365,1),ROUND((hr_analytics_dataset_5873_rows[[#This Row],[Resignation Date]]-hr_analytics_dataset_5873_rows[[#This Row],[Hire Date]])/365,1))) -> 2.4 | S17: 4
A18: EMP000017 | B18: Employee_17 | C18: Male | D18: 57 | E18: Logistics | F18: Supply Chain Analyst | G18: 45263 | H18: Resigned | I18: 45637 | J18: Bachelor | K18: Jakarta | L18: 23414742 | M18: =IF(L18<5000000,"<Rp5 jt",IF(L18<10000000,"Rp5 jt - Rp10 jt",IF(L18<15000000,"Rp10 jt - Rp15 jt",IF(L18<25000000,"Rp15 jt - Rp25 jt",">Rp25 jt")))) -> Rp15 jt - Rp25 jt | N18: 3321992 | O18: 4.62 | P18: 29 | Q18: 72.55 | R18: =IF(I18="",ROUND((TODAY()-G18)/365,1),IF(I18="Missing Resignation Date",ROUND((TODAY()-G18)/365,1),ROUND((hr_analytics_dataset_5873_rows[[#This Row],[Resignation Date]]-hr_analytics_dataset_5873_rows[[#This Row],[Hire Date]])/365,1))) -> 1 | S18: 1
A19: EMP000018 | B19: Employee_18 | C19: Female | D19: 27 | E19: Operations | F19: Operations Manager | G19: 44547 | H19: Active | J19: Diploma | K19: Yogyakarta | L19: 25102836 | M19: =IF(L19<5000000,"<Rp5 jt",IF(L19<10000000,"Rp5 jt - Rp10 jt",IF(L19<15000000,"Rp10 jt - Rp15 jt",IF(L19<25000000,"Rp15 jt - Rp25 jt",">Rp25 jt")))) -> >Rp25 jt | N19: 2009979 | O19: 3.99 | P19: 58 | Q19: 76.83 | R19: =IF(I19="",ROUND((TODAY()-G19)/365,1),IF(I19="Missing Resignation Date",ROUND((TODAY()-G19)/365,1),ROUND((hr_analytics_dataset_5873_rows[[#This Row],[Resignation Date]]-hr_analytics_dataset_5873_rows[[#This Row],[Hire Date]])/365,1))) -> 4.5 | S19: 1
A20: EMP000019 | B20: Employee_19 | C20: Male | D20: 40 | E20: Marketing | F20: Marketing Executive | G20: 44986 | H20: Resigned | I20: Missing Resignation Date | J20: High School | K20: Medan | L20: 10196456 | M20: =IF(L20<5000000,"<Rp5 jt",IF(L20<10000000,"Rp5 jt - Rp10 jt",IF(L20<15000000,"Rp10 jt - Rp15 jt",IF(L20<25000000,"Rp15 jt - Rp25 jt",">Rp25 jt")))) -> Rp10 jt - Rp15 jt | N20: 4388124 | O20: 4.62 | P20: 33 | Q20: 78.66 | R20: =IF(I20="",ROUND((TODAY()-G20)/365,1),IF(I20="Missing Resignation Date",ROUND((TODAY()-G20)/365,1),ROUND((hr_analytics_dataset_5873_rows[[#This Row],[Resignation Date]]-hr_analytics_dataset_5873_rows[[#This Row],[Hire Date]])/365,1))) -> 3.3 | S20: 2
A21: EMP000020 | B21: Employee_20 | C21: Male | D21: 34 | E21: Finance | F21: Accountant | G21: 45859 | H21: Active | J21: Bachelor | K21: Bandung | L21: 32257645 | M21: =IF(L21<5000000,"<Rp5 jt",IF(L21<10000000,"Rp5 jt - Rp10 jt",IF(L21<15000000,"Rp10 jt - Rp15 jt",IF(L21<25000000,"Rp15 jt - Rp25 jt",">Rp25 jt")))) -> >Rp25 jt | N21: 3745075 | O21: 4.23 | P21: 54 | Q21: 99.34 | R21: =IF(I21="",ROUND((TODAY()-G21)/365,1),IF(I21="Missing Resignation Date",ROUND((TODAY()-G21)/365,1),ROUND((hr_analytics_dataset_5873_rows[[#This Row],[Resignation Date]]-hr_analytics_dataset_5873_rows[[#This Row],[Hire Date]])/365,1))) -> 0.9 | S21: 5
A22: EMP000021 | B22: Employee_21 | C22: Male | D22: 40 | E22: HR | F22: HR Manager | G22: 44826 | H22: Active | J22: Diploma | K22: Bandung | L22: 17946419 | M22: =IF(L22<5000000,"<Rp5 jt",IF(L22<10000000,"Rp5 jt - Rp10 jt",IF(L22<15000000,"Rp10 jt - Rp15 jt",IF(L22<25000000,"Rp15 jt - Rp25 jt",">Rp25 jt")))) -> Rp15 jt - Rp25 jt | N22: 8283784 | O22: 3.88 | P22: 9 | Q22: 92.81 | R22: =IF(I22="",ROUND((TODAY()-G22)/365,1),IF(I22="Missing Resignation Date",ROUND((TODAY()-G22)/365,1),ROUND((hr_analytics_dataset_5873_rows[[#This Row],[Resignation Date]]-hr_analytics_dataset_5873_rows[[#This Row],[Hire Date]])/365,1))) -> 3.8 | S22: 3
A23: EMP000022 | B23: Employee_22 | C23: Male | D23: 48 | E23: Customer Service | F23: Customer Support | G23: 45608 | H23: Active | J23: High School | K23: Bandung | L23: 15987688 | M23: =IF(L23<5000000,"<Rp5 jt",IF(L23<10000000,"Rp5 jt - Rp10 jt",IF(L23<15000000,"Rp10 jt - Rp15 jt",IF(L23<25000000,"Rp15 jt - Rp25 jt",">Rp25 jt")))) -> Rp15 jt - Rp25 jt | N23: 4470922 | O23: 3.91 | P23: 43 | Q23: 85.38 | R23: =IF(I23="",ROUND((TODAY()-G23)/365,1),IF(I23="Missing Resignation Date",ROUND((TODAY()-G23)/365,1),ROUND((hr_analytics_dataset_5873_rows[[#This Row],[Resignation Date]]-hr_analytics_dataset_5873_rows[[#This Row],[Hire Date]])/365,1))) -> 1.6 | S23: 5
A24: EMP000023 | B24: Employee_23 | C24: Male | D24: 23 | E24: IT | F24: System Admin | G24: 45534 | H24: Active | J24: Master | K24: Semarang | L24: 33753077 | M24: =IF(L24<5000000,"<Rp5 jt",IF(L24<10000000,"Rp5 jt - Rp10 jt",IF(L24<15000000,"Rp10 jt - Rp15 jt",IF(L24<25000000,"Rp15 jt - Rp25 jt",">Rp25 jt")))) -> >Rp25 jt | N24: 2869011 | O24: 3.95 | P24: 59 | Q24: 94.82 | R24: =IF(I24="",ROUND((TODAY()-G24)/365,1),IF(I24="Missing Resignation Date",ROUND((TODAY()-G24)/365,1),ROUND((hr_analytics_dataset_5873_rows[[#This Row],[Resignation Date]]-hr_analytics_dataset_5873_rows[[#This Row],[Hire Date]])/365,1))) -> 1.8 | S24: 3
A25: EMP000024 | B25: Employee_24 | C25: Female | D25: 45 | E25: Operations | F25: Operations Staff | G25: 43948 | H25: Resigned | I25: 44465 | J25: Master | K25: Medan | L25: 15158635 | M25: =IF(L25<5000000,"<Rp5 jt",IF(L25<10000000,"Rp5 jt - Rp10 jt",IF(L25<15000000,"Rp10 jt - Rp15 jt",IF(L25<25000000,"Rp15 jt - Rp25 jt",">Rp25 jt")))) -> Rp15 jt - Rp25 jt | N25: 5461541 | O25: 3.23 | P25: 9 | Q25: 83.81 | R25: =IF(I25="",ROUND((TODAY()-G25)/365,1),IF(I25="Missing Resignation Date",ROUND((TODAY()-G25)/365,1),ROUND((hr_analytics_dataset_5873_rows[[#This Row],[Resignation Date]]-hr_analytics_dataset_5873_rows[[#This Row],[Hire Date]])/365,1))) -> 1.4 | S25: 5
A26: EMP000025 | B26: Employee_25 | C26: Male | D26: 47 | E26: Finance | F26: Accountant | G26: 43276 | H26: Resigned | I26: 43573 | J26: High School | K26: Jakarta | L26: 29950392 | M26: =IF(L26<5000000,"<Rp5 jt",IF(L26<10000000,"Rp5 jt - Rp10 jt",IF(L26<15000000,"Rp10 jt - Rp15 jt",IF(L26<25000000,"Rp15 jt - Rp25 jt",">Rp25 jt")))) -> >Rp25 jt | N26: 5935620 | O26: 4.72 | P26: 30 | Q26: 93.03 | R26: =IF(I26="",ROUND((TODAY()-G26)/365,1),IF(I26="Missing Resignation Date",ROUND((TODAY()-G26)/365,1),ROUND((hr_analytics_dataset_5873_rows[[#This Row],[Resignation Date]]-hr_analytics_dataset_5873_rows[[#This Row],[Hire Date]])/365,1))) -> 0.8 | S26: 3
A27: EMP000026 | B27: Employee_26 | C27: Female | D27: 36 | E27: Marketing | F27: SEO Specialist | G27: 43803 | H27: Active | J27: Diploma | K27: Jakarta | L27: 23175329 | M27: =IF(L27<5000000,"<Rp5 jt",IF(L27<10000000,"Rp5 jt - Rp10 jt",IF(L27<15000000,"Rp10 jt - Rp15 jt",IF(L27<25000000,"Rp15 jt - Rp25 jt",">Rp25 jt")))) -> Rp15 jt - Rp25 jt | N27: 9679331 | O27: 3.6 | P27: 14 | Q27: 86.09 | R27: =IF(I27="",ROUND((TODAY()-G27)/365,1),IF(I27="Missing Resignation Date",ROUND((TODAY()-G27)/365,1),ROUND((hr_analytics_dataset_5873_rows[[#This Row],[Resignation Date]]-hr_analytics_dataset_5873_rows[[#This Row],[Hire Date]])/365,1))) -> 6.6 | S27: 5
A28: EMP000027 | B28: Employee_27 | C28: Male | D28: 51 | E28: Logistics | F28: Warehouse Staff | G28: 43895 | H28: Resigned | I28: 44562 | J28: Master | K28: Yogyakarta | L28: 31548307 | M28: =IF(L28<5000000,"<Rp5 jt",IF(L28<10000000,"Rp5 jt - Rp10 jt",IF(L28<15000000,"Rp10 jt - Rp15 jt",IF(L28<25000000,"Rp15 jt - Rp25 jt",">Rp25 jt")))) -> >Rp25 jt | N28: 3106632 | O28: 4.9 | P28: 12 | Q28: 98.59 | R28: =IF(I28="",ROUND((TODAY()-G28)/365,1),IF(I28="Missing Resignation Date",ROUND((TODAY()-G28)/365,1),ROUND((hr_analytics_dataset_5873_rows[[#This Row],[Resignation Date]]-hr_analytics_dataset_5873_rows[[#This Row],[Hire Date]])/365,1))) -> 1.8 | S28: 1
A29: EMP000028 | B29: Employee_28 | C29: Female | D29: 44 | E29: Operations | F29: Operations Staff | G29: 45199 | H29: Active | J29: Bachelor | K29: Medan | L29: 26355751 | M29: =IF(L29<5000000,"<Rp5 jt",IF(L29<10000000,"Rp5 jt - Rp10 jt",IF(L29<15000000,"Rp10 jt - Rp15 jt",IF(L29<25000000,"Rp15 jt - Rp25 jt",">Rp25 jt")))) -> >Rp25 jt | N29: 4984842 | O29: 4.61 | P29: 1 | Q29: 73.82 | R29: =IF(I29="",ROUND((TODAY()-G29)/365,1),IF(I29="Missing Resignation Date",ROUND((TODAY()-G29)/365,1),ROUND((hr_analytics_dataset_5873_rows[[#This Row],[Resignation Date]]-hr_analytics_dataset_5873_rows[[#This Row],[Hire Date]])/365,1))) -> 2.7 | S29: 3
A30: EMP000029 | B30: Employee_29 | C30: Female | D30: 34 | E30: Finance | F30: Accountant | G30: 43751 | H30: Resigned | I30: 45376 | J30: High School | K30: Medan | L30: 18806654 | M30: =IF(L30<5000000,"<Rp5 jt",IF(L30<10000000,"Rp5 jt - Rp10 jt",IF(L30<15000000,"Rp10 jt - Rp15 jt",IF(L30<25000000,"Rp15 jt - Rp25 jt",">Rp25 jt")))) -> Rp15 jt - Rp25 jt | N30: 5098795 | O30: 2.84 | P30: 60 | Q30: 86.82 | R30: =IF(I30="",ROUND((TODAY()-G30)/365,1),IF(I30="Missing Resignation Date",ROUND((TODAY()-G30)/365,1),ROUND((hr_analytics_dataset_5873_rows[[#This Row],[Resignation Date]]-hr_analytics_dataset_5873_rows[[#This Row],[Hire Date]])/365,1))) -> 4.5 | S30: 5
A31: EMP000030 | B31: Employee_30 | C31: Male | D31: 42 | E31: Customer Service | F31: Call Center | G31: 45975 | H31: Resigned | I31: Missing Resignation Date | J31: Diploma | K31: Bandung | L31: 6152842 | M31: =IF(L31<5000000,"<Rp5 jt",IF(L31<10000000,"Rp5 jt - Rp10 jt",IF(L31<15000000,"Rp10 jt - Rp15 jt",IF(L31<25000000,"Rp15 jt - Rp25 jt",">Rp25 jt")))) -> Rp5 jt - Rp10 jt | N31: 6044376 | O31: 3.29 | P31: 56 | Q31: 73.57 | R31: =IF(I31="",ROUND((TODAY()-G31)/365,1),IF(I31="Missing Resignation Date",ROUND((TODAY()-G31)/365,1),ROUND((hr_analytics_dataset_5873_rows[[#This Row],[Resignation Date]]-hr_analytics_dataset_5873_rows[[#This Row],[Hire Date]])/365,1))) -> 0.6 | S31: 1
A32: EMP000031 | B32: Employee_31 | C32: Male | D32: 32 | E32: Operations | F32: Operations Manager | G32: 45503 | H32: Active | J32: Bachelor | K32: Bandung | L32: 24103248 | M32: =IF(L32<5000000,"<Rp5 jt",IF(L32<10000000,"Rp5 jt - Rp10 jt",IF(L32<15000000,"Rp10 jt - Rp15 jt",IF(L32<25000000,"Rp15 jt - Rp25 jt",">Rp25 jt")))) -> Rp15 jt - Rp25 jt | N32: 752787 | O32: 4.49 | P32: 55 | Q32: 79.52 | R32: =IF(I32="",ROUND((TODAY()-G32)/365,1),IF(I32="Missing Resignation Date",ROUND((TODAY()-G32)/365,1),ROUND((hr_analytics_dataset_5873_rows[[#This Row],[Resignation Date]]-hr_analytics_dataset_5873_rows[[#This Row],[Hire Date]])/365,1))) -> 1.9 | S32: 4
A33: EMP000032 | B33: Employee_32 | C33: Male | D33: 35 | E33: Finance | F33: Financial Analyst | G33: 44793 | H33: Active | J33: Bachelor | K33: Medan | L33: 23612531 | M33: =IF(L33<5000000,"<Rp5 jt",IF(L33<10000000,"Rp5 jt - Rp10 jt",IF(L33<15000000,"Rp10 jt - Rp15 jt",IF(L33<25000000,"Rp15 jt - Rp25 jt",">Rp25 jt")))) -> Rp15 jt - Rp25 jt | N33: 9330386 | O33: 2.88 | P33: 53 | Q33: 77.27 | R33: =IF(I33="",ROUND((TODAY()-G33)/365,1),IF(I33="Missing Resignation Date",ROUND((TODAY()-G33)/365,1),ROUND((hr_analytics_dataset_5873_rows[[#This Row],[Resignation Date]]-hr_analytics_dataset_5873_rows[[#This Row],[Hire Date]])/365,1))) -> 3.8 | S33: 3
A34: EMP000033 | B34: Employee_33 | C34: Female | D34: 28 | E34: Customer Service | F34: Customer Support | G34: 44302 | H34: Active | J34: Bachelor | K34: Yogyakarta | L34: 15952207 | M34: =IF(L34<5000000,"<Rp5 jt",IF(L34<10000000,"Rp5 jt - Rp10 jt",IF(L34<15000000,"Rp10 jt - Rp15 jt",IF(L34<25000000,"Rp15 jt - Rp25 jt",">Rp25 jt")))) -> Rp15 jt - Rp25 jt | N34: 9564269 | O34: 3.94 | P34: 56 | Q34: 75.37 | R34: =IF(I34="",ROUND((TODAY()-G34)/365,1),IF(I34="Missing Resignation Date",ROUND((TODAY()-G34)/365,1),ROUND((hr_analytics_dataset_5873_rows[[#This Row],[Resignation Date]]-hr_analytics_dataset_5873_rows[[#This Row],[Hire Date]])/365,1))) -> 5.2 | S34: 2
A35: EMP000034 | B35: Employee_34 | C35: Female | D35: 55 | E35: Marketing | F35: SEO Specialist | G35: 43816 | H35: Active | J35: Master | K35: Semarang | L35: 4459416 | M35: =IF(L35<5000000,"<Rp5 jt",IF(L35<10000000,"Rp5 jt - Rp10 jt",IF(L35<15000000,"Rp10 jt - Rp15 jt",IF(L35<25000000,"Rp15 jt - Rp25 jt",">Rp25 jt")))) -> <Rp5 jt | N35: 5443043 | O35: 4.17 | P35: 4 | Q35: 90.02 | R35: =IF(I35="",ROUND((TODAY()-G35)/365,1),IF(I35="Missing Resignation Date",ROUND((TODAY()-G35)/365,1),ROUND((hr_analytics_dataset_5873_rows[[#This Row],[Resignation Date]]-hr_analytics_dataset_5873_rows[[#This Row],[Hire Date]])/365,1))) -> 6.5 | S35: 1
A36: EMP000035 | B36: Employee_35 | C36: Female | D36: 26 | E36: Finance | F36: Financial Analyst | G36: 45916 | H36: Resigned | I36: Missing Resignation Date | J36: Bachelor | K36: Surabaya | L36: 25353719 | M36: =IF(L36<5000000,"<Rp5 jt",IF(L36<10000000,"Rp5 jt - Rp10 jt",IF(L36<15000000,"Rp10 jt - Rp15 jt",IF(L36<25000000,"Rp15 jt - Rp25 jt",">Rp25 jt")))) -> >Rp25 jt | N36: 4816866 | O36: 2.84 | P36: 57 | Q36: 98.47 | R36: =IF(I36="",ROUND((TODAY()-G36)/365,1),IF(I36="Missing Resignation Date",ROUND((TODAY()-G36)/365,1),ROUND((hr_analytics_dataset_5873_rows[[#This Row],[Resignation Date]]-hr_analytics_dataset_5873_rows[[#This Row],[Hire Date]])/365,1))) -> 0.8 | S36: 4
A37: EMP000036 | B37: Employee_36 | C37: Male | D37: 54 | E37: Finance | F37: Accountant | G37: 45194 | H37: Active | J37: Bachelor | K37: Bandung | L37: 6809904 | M37: =IF(L37<5000000,"<Rp5 jt",IF(L37<10000000,"Rp5 jt - Rp10 jt",IF(L37<15000000,"Rp10 jt - Rp15 jt",IF(L37<25000000,"Rp15 jt - Rp25 jt",">Rp25 jt")))) -> Rp5 jt - Rp10 jt | N37: 2898774 | O37: 4.11 | P37: 50 | Q37: 80.24 | R37: =IF(I37="",ROUND((TODAY()-G37)/365,1),IF(I37="Missing Resignation Date",ROUND((TODAY()-G37)/365,1),ROUND((hr_analytics_dataset_5873_rows[[#This Row],[Resignation Date]]-hr_analytics_dataset_5873_rows[[#This Row],[Hire Date]])/365,1))) -> 2.7 | S37: 1
A38: EMP000037 | B38: Employee_37 | C38: Male | D38: 49 | E38: Logistics | F38: Supply Chain Analyst | G38: 44167 | H38: Active | J38: Diploma | K38: Bandung | L38: 21462766 | M38: =IF(L38<5000000,"<Rp5 jt",IF(L38<10000000,"Rp5 jt - Rp10 jt",IF(L38<15000000,"Rp10 jt - Rp15 jt",IF(L38<25000000,"Rp15 jt - Rp25 jt",">Rp25 jt")))) -> Rp15 jt - Rp25 jt | N38: 7248097 | O38: 4.75 | P38: 36 | Q38: 98.23 | R38: =IF(I38="",ROUND((TODAY()-G38)/365,1),IF(I38="Missing Resignation Date",ROUND((TODAY()-G38)/365,1),ROUND((hr_analytics_dataset_5873_rows[[#This Row],[Resignation Date]]-hr_analytics_dataset_5873_rows[[#This Row],[Hire Date]])/365,1))) -> 5.6 | S38: 1
A39: EMP000038 | B39: Employee_38 | C39: Male | D39: 38 | E39: Sales | F39: Sales Executive | G39: 43805 | H39: Active | J39: Diploma | K39: Surabaya | L39: 6905628 | M39: =IF(L39<5000000,"<Rp5 jt",IF(L39<10000000,"Rp5 jt - Rp10 jt",IF(L39<15000000,"Rp10 jt - Rp15 jt",IF(L39<25000000,"Rp15 jt - Rp25 jt",">Rp25 jt")))) -> Rp5 jt - Rp10 jt | N39: 3557270 | O39: 4.78 | P39: 37 | Q39: 80.78 | R39: =IF(I39="",ROUND((TODAY()-G39)/365,1),IF(I39="Missing Resignation Date",ROUND((TODAY()-G39)/365,1),ROUND((hr_analytics_dataset_5873_rows[[#This Row],[Resignation Date]]-hr_analytics_dataset_5873_rows[[#This Row],[Hire Date]])/365,1))) -> 6.6 | S39: 2
A40: EMP000039 | B40: Employee_39 | C40: Female | D40: 40 | E40: Finance | F40: Financial Analyst | G40: 45849 | H40: Active | J40: Bachelor | K40: Surabaya | L40: 20205317 | M40: =IF(L40<5000000,"<Rp5 jt",IF(L40<10000000,"Rp5 jt - Rp10 jt",IF(L40<15000000,"Rp10 jt - Rp15 jt",IF(L40<25000000,"Rp15 jt - Rp25 jt",">Rp25 jt")))) -> Rp15 jt - Rp25 jt | N40: 1169010 | O40: 4.38 | P40: 58 | Q40: 84.38 | R40: =IF(I40="",ROUND((TODAY()-G40)/365,1),IF(I40="Missing Resignation Date",ROUND((TODAY()-G40)/365,1),ROUND((hr_analytics_dataset_5873_rows[[#This Row],[Resignation Date]]-hr_analytics_dataset_5873_rows[[#This Row],[Hire Date]])/365,1))) -> 1 | S40: 3
...

Sheet ANALISA HR EMPLOYEE
B2: HR ANALYTIC
B4: Total Employee
B5: Row Labels | C5: Count of Employee ID | J5: Row Labels | K5: Count of Employee ID
B6: HR | C6: 703 | J6: Female | K6: 2893
B7: Marketing | C7: 704 | J7: Male | K7: 2980
B8: Customer Service | C8: 708 | J8: Grand Total | K8: 5873
B9: Sales | C9: 729
B10: Logistics | C10: 735
B11: Finance | C11: 750
B12: IT | C12: 761
B13: Operations | C13: 783
B14: Grand Total | C14: 5873
B17: Attrition By Department
B18: Count of Employee ID | C18: Column Labels | J18: Row Labels | K18: Count of Employee ID
B19: Row Labels | C19: Resigned | J19: 2018 | K19: 765
B20: Marketing | C20: 0.1115348 | J20: 2019 | K20: 696
B21: Customer Service | C21: 0.11248808 | J21: 2020 | K21: 728
B22: HR | C22: 0.12106768 | J22: 2021 | K22: 704
B23: IT | C23: 0.12583413 | J23: 2022 | K23: 751
B24: Logistics | C24: 0.12869399 | J24: 2023 | K24: 757
B25: Sales | C25: 0.12964728 | J25: 2024 | K25: 737
B26: Finance | C26: 0.13536702 | J26: 2025 | K26: 735
B27: Operations | C27: 0.13536702 | J27: Grand Total | K27: 5873
B34: Attritition Rate
B35: Row Labels | C35: Count of Employee ID | L35: Average Salary vs Average Performance Rate
B36: Active | C36: 0.821386 | L36: Employment Status | M36: All
B37: Resigned | C37: 0.178614
B38: Grand Total | C38: 1 | L38: Row Labels | M38: Average of Monthly Salary | N38: Average of Performance Score
L39: Customer Service | M39: 19449803 | N39: 3.6070621
L40: Finance | M40: 19960478 | N40: 3.6907333
B41: Average Salary | L41: HR | M41: 19692607 | N41: 3.6637269
C42: Column Labels | E42: Count of Employee ID | F42: Column Labels | L42: IT | M42: 19635870 | N42: 3.6935611
C43: Active | D43: Resigned | E43: Row Labels | F43: Active | L43: Logistics | M43: 19527854 | N43: 3.6637823
B44: Average of Monthly Salary | C44: 19451741 | D44: 19679013 | E44: <Rp5 jt | F44: 0.032545605 | L44: Marketing | M44: 18909817 | N44: 3.6049574
E45: Rp5 jt - Rp10 jt | F45: 0.16355721 | L45: Operations | M45: 19204505 | N45: 3.663295
E46: Rp10 jt - Rp15 jt | F46: 0.16355721 | L46: Sales | M46: 19544932 | N46: 3.6723594
E47: Rp15 jt - Rp25 jt | F47: 0.32006633
E48: >Rp25 jt | F48: 0.32027363
B50: Row Labels | C50: Count of Employee ID
B51: Active | C51: 4824 | L51: Average Attendance Rate
...

Sheet PORTOFOLIO DATA
A2: DASHBOARD ANALISIS HR
B4: Total Karyawan | C4: =GETPIVOTDATA("[Measures].[Count of Employee ID]",'ANALISA HR EMPLOYEE'!$B$50) -> 5873 | E4: Total Karyawan Aktif | F4: =GETPIVOTDATA("[Measures].[Count of Employee ID]",'ANALISA HR EMPLOYEE'!$B$50,"[hr_analytics_dataset_5873_rows].[Employment Status]","[hr_analytics_dataset_5873_rows].[Employment Status].&[Active]") -> 4824 | H4: Total Karyawan Resign | I4: =GETPIVOTDATA("[Measures].[Count of Employee ID]",'ANALISA HR EMPLOYEE'!$B$50,"[hr_analytics_dataset_5873_rows].[Employment Status]","[hr_analytics_dataset_5873_rows].[Employment Status].&[Resigned]") -> 1049 | K4: Rata - Rata Gaji | L4: =GETPIVOTDATA("[Measures].[Average of Monthly Salary]",'ANALISA HR EMPLOYEE'!$B$42,"[hr_analytics_dataset_5873_rows].[Employment Status]","[hr_analytics_dataset_5873_rows].[Employment Status].&[Active]")/1000000 -> 19.451741
B6: Tingkat Turnover karyawan | C6: =GETPIVOTDATA("[Measures].[Count of Employee ID]",'ANALISA HR EMPLOYEE'!$B$35,"[hr_analytics_dataset_5873_rows].[Employment Status]","[hr_analytics_dataset_5873_rows].[Employment Status].&[Resigned]") -> 0.178614 | E6: Rata - rata Tingkat Kehadiran Karyawan | F6: =GETPIVOTDATA("[Measures].[Average of Attendance Rate (%)]",'ANALISA HR EMPLOYEE'!$B$56)/100 -> 0.83826537 | H6: Rata - rata Tingkat Nilai Performance | I6: =GETPIVOTDATA("[Measures].[Average of Performance Score]",'ANALISA HR EMPLOYEE'!$B$60) -> 3.6581866
F54: Turnover tertinggi : Operations dan Marketing
F56: Terdapat korelasi positif moderat antara gaji dan performa (R2 = 0,51)
F58: Tren perekrutan menunjukkan pemulihan setelah penurunan di 2021
F60: Sebagian besar karyawan mendapatkan gaji di atas Rp15 juta
F62: Missing type : status resign tanpa tanggal resignation

Sheet hr_analytics_dataset_5873_rows
A1: Employee ID,Employee Name,Gender,Age,Department,Job Role,Hire Date,Employment Status,Resignation Date,Education Level,Region,Monthly Salary,Bonus,Performance Score,Overtime Hours,Attendance Rate (%),Years at Company,Job Satisfaction
A2: EMP000001,Employee_1,Female,48,Sales,Sales Manager,2019-05-30,Active,,Master,Bandung,18831984,5723038,4.91,15,98.03,6.6,4
A3: EMP000002,Employee_2,Male,26,IT,System Admin,2020-10-26,Resigned,2026-04-04,Diploma,Bandung,33418624,541210,3.47,55,99.01,5.2,4
A4: EMP000003,Employee_3,Female,36,Operations,Operations Manager,2025-05-08,Active,,High School,Surabaya,15519850,1322362,3.13,46,80.86,0.6,2
A5: EMP000004,Employee_4,Female,39,Marketing,Marketing Executive,2021-02-19,Active,,High School,Bandung,7673135,5803373,4.48,58,97.08,4.9,3
A6: EMP000005,Employee_5,Male,56,IT,Data Analyst,2023-07-01,Resigned,2026-02-19,Bachelor,Semarang,25941260,1286723,3.43,19,75.48,2.5,1
A7: EMP000006,Employee_6,Male,57,Logistics,Supply Chain Analyst,2023-05-24,Active,,Diploma,Surabaya,26677346,9908304,3.36,15,78.65,2.6,4
A8: EMP000007,Employee_7,Female,24,Logistics,Supply Chain Analyst,2019-04-07,Active,,Bachelor,Bandung,25806571,3832514,3.93,34,87.43,6.7,5
A9: EMP000008,Employee_8,Female,28,HR,Recruiter,2025-06-15,Active,,Bachelor,Medan,14576147,5328081,4.65,20,70.49,0.5,2
A10: EMP000009,Employee_9,Female,44,Operations,Operations Manager,2021-04-06,Active,,Master,Yogyakarta,28171681,2716525,4.78,43,76.19,4.7,1
A11: EMP000010,Employee_10,Male,27,Operations,Operations Manager,2020-12-03,Resigned,2025-03-06,High School,Bandung,11630453,2850529,4.52,18,97.16,5.1,3
A12: EMP000011,Employee_11,Female,44,Sales,Sales Executive,2024-12-30,Active,,Bachelor,Medan,24453900,3194035,2.98,18,88.68,1.0,2
... A5921: EMP003997,Employee_3997,Male,30,IT,System Admin,2021-10-01,Resigned,2024-02-23,Master,Jakarta,17878203,7920431,3.9,35,78.95,4.3,3

Sheet Sheet1
A2: Row Labels | B2: Average of Monthly Salary | C2: Average of Performance Score
A3: Customer Service | B3: 19449803 | C3: 3.6070621
A4: Finance | B4: 19960478 | C4: 3.6907333
A5: HR | B5: 19692607 | C5: 3.6637269
A6: IT | B6: 19635870 | C6: 3.6935611
A7: Logistics | B7: 19527854 | C7: 3.6637823
A8: Marketing | B8: 18909817 | C8: 3.6049574
A9: Operations | B9: 19204505 | C9: 3.663295
A10: Sales | B10: 19544932 | C10: 3.6723594
